{"name": "test_init_wx", "status": "broken", "statusDetails": {"message": "pymysql.err.InternalError: (1054, \"Unknown column 'user_id' in 'field list'\")", "trace": "self = <testcases.init_test.test_init_phone.TestInitPhone object at 0x102b783c8>\n\n    def test_init_wx(self):\n        sql = \"select user_id from user where phone = '13656640242'\"\n>       data = db.select_db(sql)\n\ntest_init_phone.py:9: \n_ _ _ _ _ _ _ _ _ _ _ _ _ _ _ _ _ _ _ _ _ _ _ _ _ _ _ _ _ _ _ _ _ _ _ _ _ _ _ _ \n../../common/mysql_operate.py:38: in select_db\n    self.cur.execute(sql)\n../../venv/lib/python3.7/site-packages/pymysql/cursors.py:170: in execute\n    result = self._query(query)\n../../venv/lib/python3.7/site-packages/pymysql/cursors.py:328: in _query\n    conn.query(q)\n../../venv/lib/python3.7/site-packages/pymysql/connections.py:517: in query\n    self._affected_rows = self._read_query_result(unbuffered=unbuffered)\n../../venv/lib/python3.7/site-packages/pymysql/connections.py:732: in _read_query_result\n    result.read()\n../../venv/lib/python3.7/site-packages/pymysql/connections.py:1075: in read\n    first_packet = self.connection._read_packet()\n../../venv/lib/python3.7/site-packages/pymysql/connections.py:684: in _read_packet\n    packet.check_error()\n../../venv/lib/python3.7/site-packages/pymysql/protocol.py:220: in check_error\n    err.raise_mysql_exception(self._data)\n_ _ _ _ _ _ _ _ _ _ _ _ _ _ _ _ _ _ _ _ _ _ _ _ _ _ _ _ _ _ _ _ _ _ _ _ _ _ _ _ \n\ndata = b\"\\xff\\x1e\\x04#42S22Unknown column 'user_id' in 'field list'\"\n\n    def raise_mysql_exception(data):\n        errno = struct.unpack('<h', data[1:3])[0]\n        is_41 = data[3:4] == b\"#\"\n        if is_41:\n            # client protocol 4.1\n            errval = data[9:].decode('utf-8', 'replace')\n        else:\n            errval = data[3:].decode('utf-8', 'replace')\n        errorclass = error_map.get(errno, InternalError)\n>       raise errorclass(errno, errval)\nE       pymysql.err.InternalError: (1054, \"Unknown column 'user_id' in 'field list'\")\n\n../../venv/lib/python3.7/site-packages/pymysql/err.py:109: InternalError"}, "start": 1635491195571, "stop": 1635491195652, "uuid": "4aea96e0-c5cb-426b-97a0-457ac528242a", "historyId": "8c0fae4751153b61f543c66638e7ac4e", "testCaseId": "314b4765a31164db261c4e994766b604", "fullName": "testcases.init_test.test_init_phone.TestInitPhone#test_init_wx", "labels": [{"name": "parentSuite", "value": "testcases.init_test"}, {"name": "suite", "value": "test_init_phone"}, {"name": "subSuite", "value": "TestInitPhone"}, {"name": "host", "value": "tongchunyan.local"}, {"name": "thread", "value": "6609-MainThread"}, {"name": "framework", "value": "pytest"}, {"name": "language", "value": "cpython3"}, {"name": "package", "value": "testcases.init_test.test_init_phone"}]}