{"name": "test_init_wx[13656640241-1831]", "status": "broken", "statusDetails": {"message": "pymysql.err.InternalError: (1054, \"Unknown column 'user_id' in 'where clause'\")", "trace": "self = <testcases.init_test.test_init_phone.TestInitPhone object at 0x10d7479e8>\nphone = '13656640241', userID = '1831'\n\n    @pytest.mark.parametrize(\"phone, userID\", api_data[\"test_init_wx\"])\n    def test_init_wx(self, phone, userID):\n        \"\"\"批量初始化手机号为新用户\"\"\"\n        sql = \"select id as user_id from user where phone ='%s' or user_id = '%s' \" % (phone, userID)\n>       data = db.select_db(sql)\n\ntest_init_phone.py:14: \n_ _ _ _ _ _ _ _ _ _ _ _ _ _ _ _ _ _ _ _ _ _ _ _ _ _ _ _ _ _ _ _ _ _ _ _ _ _ _ _ \n../../common/mysql_operate.py:40: in select_db\n    self.cur.execute(sql)\n../../venv/lib/python3.7/site-packages/pymysql/cursors.py:170: in execute\n    result = self._query(query)\n../../venv/lib/python3.7/site-packages/pymysql/cursors.py:328: in _query\n    conn.query(q)\n../../venv/lib/python3.7/site-packages/pymysql/connections.py:517: in query\n    self._affected_rows = self._read_query_result(unbuffered=unbuffered)\n../../venv/lib/python3.7/site-packages/pymysql/connections.py:732: in _read_query_result\n    result.read()\n../../venv/lib/python3.7/site-packages/pymysql/connections.py:1075: in read\n    first_packet = self.connection._read_packet()\n../../venv/lib/python3.7/site-packages/pymysql/connections.py:684: in _read_packet\n    packet.check_error()\n../../venv/lib/python3.7/site-packages/pymysql/protocol.py:220: in check_error\n    err.raise_mysql_exception(self._data)\n_ _ _ _ _ _ _ _ _ _ _ _ _ _ _ _ _ _ _ _ _ _ _ _ _ _ _ _ _ _ _ _ _ _ _ _ _ _ _ _ \n\ndata = b\"\\xff\\x1e\\x04#42S22Unknown column 'user_id' in 'where clause'\"\n\n    def raise_mysql_exception(data):\n        errno = struct.unpack('<h', data[1:3])[0]\n        is_41 = data[3:4] == b\"#\"\n        if is_41:\n            # client protocol 4.1\n            errval = data[9:].decode('utf-8', 'replace')\n        else:\n            errval = data[3:].decode('utf-8', 'replace')\n        errorclass = error_map.get(errno, InternalError)\n>       raise errorclass(errno, errval)\nE       pymysql.err.InternalError: (1054, \"Unknown column 'user_id' in 'where clause'\")\n\n../../venv/lib/python3.7/site-packages/pymysql/err.py:109: InternalError"}, "description": "批量初始化手机号为新用户", "parameters": [{"name": "phone", "value": "'13656640241'"}, {"name": "userID", "value": "'1831'"}], "start": 1644808142489, "stop": 1644808142552, "uuid": "b5a2d145-5fdb-4173-bcc0-082ebb8c97b5", "historyId": "1c8763639a5b444c5f6d9f1ca221a292", "testCaseId": "314b4765a31164db261c4e994766b604", "fullName": "testcases.init_test.test_init_phone.TestInitPhone#test_init_wx", "labels": [{"name": "parentSuite", "value": "testcases.init_test"}, {"name": "suite", "value": "test_init_phone"}, {"name": "subSuite", "value": "TestInitPhone"}, {"name": "host", "value": "tongchunyan.local"}, {"name": "thread", "value": "77307-MainThread"}, {"name": "framework", "value": "pytest"}, {"name": "language", "value": "cpython3"}, {"name": "package", "value": "testcases.init_test.test_init_phone"}]}